/*注意： 在处理异常的时候 catch里面不能空着 否则 你就是把异常给隐藏掉了
 * 
 * */
package 异常;

public class ExceptionDemo4 {
	public static void main(String[] args) {
		
		int a=10;
		int b=0;
		
		
		try{
			System.out.println(a/b);
		}catch(ArithmeticException e){
			System.out.println("这里是经过异常处理的");
		}
		System.out.println("over");

	}

}
